

<mujoco model="testbody"> # XML-File wird dadurch als MJCF-File erkannt

  ############################## Simulationseinstellung ##############################
  <option timestep="0.001" iterations="150" apirate="1000" gravity="0 0 -9.81" solver="Newton" tolerance="1e-10" cone="elliptic"/>

 ############################## Modellerstellung ##############################
 <worldbody>

    <!-- <body name= "b0_pylon" pos="0.42 0.38 0.3" euler="0 0 0"> // Klemmung an Kette 1 -->
    <!-- <body name= "b0_pylon" pos="-0.535 0.175 0.3" euler="0 0 0"> // Klemmung an Kette 2 -->
    <!-- <body name= "b0_pylon" pos="0.13 -0.545 0.3" euler="0 0 0"> // Klemmung an Kette 3 -->
    <!-- <body name= "b0_pylon" pos="0.06 0.15 0.3" euler="0 0 0"> // Kollision am mP -->
    <!-- <body name= "b0_pylon" pos="0.6 0.4 0.3" euler="0 0 0"> // Kollision an C1L1 -->
    <!-- <body name= "b0_pylon" pos="0.2 0.3 0.3" euler="0 0 0"> // Kollision an C1L2 -->
    <body name= "b0_pylon" pos="0 0.2 0.3" euler="0 0 0"> // Kollision an mP
    <geom name="g3_pylon" type="capsule" size="0.05 0.2" pos="0 0 0" rgba="0 1.2 0.0 1"/>
    <joint type="slide" name="joint_body_x_transl" pos="0 0 0" axis="1 0 0" limited="false" stiffness="0" damping="0" frictionloss="0" />
    <joint type="slide" name="joint_body_y_transl" pos="0 0 0" axis="0 1 0" limited="false" stiffness="0" damping="0" frictionloss="0" />
  </body>

  </worldbody>

 ############################## Aktorendefinition ##############################
  <actuator>
    <position name="body_x" joint="joint_body_x_transl" kp="5000"/>
    <velocity name="body_xv" joint="joint_body_x_transl" kv="500" />
    <position name="body_y" joint="joint_body_y_transl" kp="5000"/>
    <velocity name="body_yv" joint="joint_body_y_transl" kv="500" />
  </actuator>

</mujoco>
